Workbook
Name acreft: '13. Conversions'!$A$20
Name cubicft: '13. Conversions'!$A$19
Name cubicm: '13. Conversions'!$A$16
Name day: '13. Conversions'!$A$5
Name gal: '13. Conversions'!$A$18
Name hr: '13. Conversions'!$A$6
Name kg: '13. Conversions'!$A$13
Name lce: '13. Conversions'!$A$24
Name lhe: '13. Conversions'!$A$26
Name li: '13. Conversions'!$A$23
Name li2o: '13. Conversions'!$A$25
Name liter: '13. Conversions'!$A$17
Name min: '13. Conversions'!$A$7
Name sec: '13. Conversions'!$A$8
Name ston: '13. Conversions'!$A$12
Name ton: '13. Conversions'!$A$11
Name yr: '13. Conversions'!$A$4

Sheet 1. Introduction & Notes
A3: This is the Supporting Information for "Future U.S. lithium production with water and socioeconomic-climate considerations"
A14: Table S1A. Watershed Names, Acronyms, and HUC8 IDs
A16: Name | B16: States | C16: Acronym | D16: HUC8
A17: Ralston-Stone Cabin Valleys | B17: NV | C17: RSCV | D17: 16060011
A18: Burro | B18: AZ | C18: BUR | D18: 15030202
A19: Big Sandy | B19: AZ | C19: BS | D19: 15030201
A20: Salton Sea | B20: CA, MX | C20: SS | D20: 18100204
A21: Cactus-Sarcobatus Flats | B21: NV | C21: CSF | D21: 16060013
A22: Southern Big Smoky Valley | B22: NV | C22: SBSV | D22: 16060003
A23: Upper Broad | B23: NC | C23: UB | D23: 3050105
A24: Upper Quinn | B24: NV, OR | C24: UQ | D24: 16040201
A25: Upper Colorado-Kane Springs | B25: UT | C25: UCKS | D25: 14030005
A26: South Fork Catawba | B26: NC | C26: SFC | D26: 3050102
A27: Fish Lake-Soda Spring Valleys | B27: NV | C27: FLSSV | D27: 16060010
A28: Bodcau Bayou | B28: AR, LA | C28: BB | D28: 11140205

Sheet 2. Lithium Content in Resources
A2: Table S2A. Lithium content in brine resources from literature
A3: Authors | B3: Date | C3: Geography | D3: Country | E3: Resource | F3: Lithium Content | G3: Unit | H3: Notes
A4: Schomberg et al | B4: 2021 | C4: Salar de Atacama | D4: Chile | E4: Concentrated brine | F4: 6.7 | G4: % | H4: Ecoinvent value
C5: Salar de Uyuni | D5: Bolivia | E5: Concentrated brine | F5: 6.7 | G5: % | H5: Ecoinvent value
C6: Salar de Hombre Muerto | D6: Argentina | E6: Concentrated brine | F6: 6.7 | G6: % | H6: Ecoinvent value
A7: Kelly et al. | B7: 2021 | C7: Salar de Atacama | D7: Chile | E7: Raw brine | F7: 0.17 | G7: %
E8: Concentrated brine | F8: 6 | G8: %
A9: Chordia et al. | B9: 2022 | C9: Salar de Cauchari | D9: Argentina | E9: Raw brine | F9: 0.05 | G9: %
E10: Concentrated brine | F10: 4.3 | G10: %
C11: Salar de Marcunga | D11: Chile | E11: Raw brine | F11: 0.09 | G11: %
E12: Concentrated brine | F12: 0.9 | G12: %
A13: Schenker et al. | B13: 2022 | C13: Salar de Atacama | D13: Chile | E13: Raw brine | F13: 0.15 | G13: % | H13: Data from 2004
E14: Concentrated brine | F14: 6 | G14: % | H14: Data from 2004
C15: Salar de Olaroz | D15: Argentina | E15: Raw brine | F15: 0.06 | G15: %
E16: Concentrated brine | F16: 1.2 | G16: %
C17: Salar de Cauchari-Olaroz | D17: Argentina | E17: Raw brine | F17: 0.05 | G17: %
E18: Concentrated brine | F18: 4 | G18: %
C19: Salar del Hombre Muerto | D19: Argentina | E19: Raw brine | F19: 0.07 | G19: %
E20: Concentrated brine | F20: 4 | G20: %
C21: Chaerhan salt lake | D21: China | E21: Raw brine | F21: 0.022 | G21: %
A22: Schenker and Pfister | B22: 2025 | C22: Salar de Atacama | D22: Chile | E22: Raw brine | F22: 0.15 | G22: %
C23: Tres Quebradas | D23: Argentina | E23: Raw brine | F23: 0.1 | G23: %
C24: Salar de Maricunga | D24: Chile | E24: Raw brine | F24: 0.09 | G24: %
C25: Sal de Vida | D25: Argentina | E25: Raw brine | F25: 0.08 | G25: %
C26: Salar de Hombre Muerto North | D26: Argentina | E26: Raw brine | F26: 0.07 | G26: %
C27: Salar de Cauchari-Olaroz | D27: Argentina | E27: Raw brine | F27: 0.05 | G27: %
C28: Pastos Grandes | D28: Argentina | E28: Raw brine | F28: 0.04 | G28: %
C29: Salar de Olaroz | D29: Argentina | E29: Raw brine | F29: 0.06 | G29: %
C30: Silver Peak | D30: USA | E30: Raw brine | F30: 0.02 | G30: %
C31: Salar de Uyuni | D31: Bolivia | E31: Raw brine | F31: 0.07 | G31: %
C32: Fénix | D32: Argentina | E32: Raw brine | F32: 0.07 | G32: %
C33: Rio Grande | D33: Argentina | E33: Raw brine | F33: 0.03 | G33: %
C34: Centenario | D34: Argentina | E34: Raw brine | F34: 0.03 | G34: %
... C46: Salton Sea | D46: USA | E46: Raw brine | F46: 0.02 | G46: %
A47: Mas-Fons et al. | B47: 2024 | C47: Salar de Atacama | D47: Chile | E47: Raw brine | F47: 0.1048 | G47: % | H47: High grade
E48: Raw brine | F48: 0.0347 | G48: % | H48: Medium grade
E49: Raw brine | F49: 0.0038 | G49: % | H49: Low grade
A53: Table S2B. Lithium content in hard-rock resources from literature
A54: Authors | B54: Date | C54: Geography | D54: Country | E54: Resource | F54: Lithium Content | G54: Unit | H54: Notes
A55: Kelly et al. | B55: 2021 | C55: Western Australia | D55: Australia | E55: Spodumene ore | F55: 0.8 | G55: % | H55: Li2O content
...

Sheet 3. Literature LCI Values
A2: Table S3A. Life Cycle Inventory (LCI) water consumption data from literature for brine resources to lithium carbonate equivalent (LCE)
A3: Title | B3: Authors | C3: Date | D3: Geography | E3: Country | F3: Extraction Process | G3: Input | H3: Input value | I3: Input unit | J3: Functional unit | K3: Notes
A4: Extended life cycle assessment reveals the spatially-explicit water scarcity footprint of a lithium-ion battery storage | B4: Schomberg et al | C4: 2021 | D4: Salar de Atacama | E4: Chile | F4: Evaporation | G4: Concentrated brine | H4: 4.19 | I4: kg | J4: kg LCE
G5: Evaporated water | H5: 40.5089 | I5: kg | J5: kg concentrated brine
H6: =H5*H4 -> 169.73229 | I6: kg | J6: kg LCE | K6: Calculated
G7: Freshwater consumption processing | H7: 0.414 | I7: kg | J7: kg concentrated brine
H8: =H7*H4 -> 1.73466 | I8: kg | J8: kg LCE | K8: Calculated
G9: Total direct water consumption | H9: =SUM(H8,H6) -> 171.46695 | I9: kg | J9: kg LCE
D10: Salar de Uyuni | E10: Bolivia | F10: Evaporation | G10: Raw brine | H10: 0.06667 | I10: kg | J10: kg LCE
G11: Concentrated brine | H11: =H10 -> 0.06667 | I11: kg | J11: kg LCE
G12: Evaporated water | H12: 163.6605 | I12: kg | J12: kg concentrated brine
H13: =H12*H11 -> 10.911246 | I13: kg | J13: kg LCE | K13: Calculated
G14: Freshwater consumption processing | H14: 0.1646 | I14: kg | J14: kg concentrated brine
H15: =H14*H11 -> 0.010973882 | I15: kg | J15: kg LCE | K15: Calculated
G16: Total direct water consumption | H16: =SUM(H15,H13) -> 10.922219 | I16: kg | J16: kg LCE
D17: Salar de Hombre Muerto | E17: Argentina | F17: Evaporation | G17: Raw brine | H17: 0.06667 | I17: kg | J17: kg LCE
G18: Concentrated brine | H18: =H17 -> 0.06667 | I18: kg | J18: kg LCE
G19: Evaporated water | H19: 98.215 | I19: kg | J19: kg concentrated brine
H20: =H19*H18 -> 6.547994 | I20: kg | J20: kg LCE | K20: Calculated
G21: Freshwater consumption processing | H21: 0.0991 | I21: kg | J21: kg concentrated brine
H22: =H21*H18 -> 0.006606997 | I22: kg | J22: kg LCE | K22: Calculated
G23: Total direct water consumption | H23: =SUM(H22,H20) -> 6.554601 | I23: kg | J23: kg LCE
A24: Energy, greenhouse gas, and water life cycle analysis of lithium carbonate and lithium hydroxide monohydrate from brine and ore resources and their use in lithium ion battery cathodes and lithium ion batteries | B24: Kelly et al. | C24: 2021 | D24: Salar de Atacama | E24: Chile | F24: Evaporation | G24: Raw brine | H24: 24.1 | I24: t | J24: t concentrated brine
H25: 96.4 | I25: t | J25: t LCE
G26: Freshwater consumption processing | H26: 2.4 | I26: m3 | J26: t concentrated brine | K26: Mass allocation value
H27: =H26/H24*H25 -> 9.6 | I27: m3 | J27: t LCE | K27: Calculated
H28: =H27*1000 -> 9600 | I28: kg | J28: t LCE | K28: Assume water density 1000 kg/m3
G29: Evaporated water | H29: 0 | I29: m3 | J29: t LCE | K29: Assume that brine is not freshwater and therefore no consumptive loss from evaporation
G30: Total direct water consumption | H30: =SUM(H29,H27) -> 9.6 | I30: m3 | J30: t LCE
H31: =H30 -> 9.6 | I31: kg | J31: kg LCE | K31: Assume water density 1000 kg/m3
A32: Life cycle environmental impacts of current and future battery-grade lithium supply from brine and spodumene | B32: Chordia et al. | C32: 2022 | D32: Salar de Cauchari | E32: Argentina | F32: Evaporation | G32: Concentrated brine | H32: 5.15 | I32: t | J32: t LCE
G33: Evaporated water | H33: 87.6 | I33: t | J33: t concentrated brine
H34: =H33*H32 -> 451.14 | I34: t | J34: t LCE
H35: =H34 -> 451.14 | I35: m3 | J35: t LCE | K35: Assume water density 1000 kg/m3
G36: Freshwater consumption processing | H36: 0 | I36: m3 | J36: t LCE
G37: Total direct water consumption | H37: =SUM(H36,H35) -> 451.14 | I37: m3 | J37: t LCE
H38: =H37 -> 451.14 | I38: kg | J38: kg LCE | K38: Assume water density 1000 kg/m3
D39: Salar de Maricunga | E39: Chile | F39: Evaporation | G39: Concentrated brine | H39: 36.9 | I39: t | J39: t LCE
G40: Evaporated water | H40: 7.14 | I40: t | J40: t concentrated brine
H41: =H40*H39 -> 263.466 | I41: t | J41: t LCE
...

Sheet 4. Proposed Mine LOM & Resource
A2: Table S4A. Proposed Mine Geographic Location, Stage, Deposit and Mine Types, and Ore and Product Reserves and Resources
I3: Ore/Brine Resources (Mt) | M3: Lithium Content/Grade (ppm, except when noted) | Q3: Product Resources (Mt) | W3: Ore/Brine Reserves (Mt) | Z3: Lithium Content/Grade (ppm, expect when noted) | AC3: Product Reserves (Mt)
A4: Proposed Site Name | B4: State | C4: Latitude | D4: Longitude | E4: Stage | F4: Deposit Type | G4: Mine Type | H4: Extraction Process | I4: Measured | J4: Indicated | K4: Measured & Indicated | L4: Inferred | M4: Measured | N4: Indicated | O4: Measured & Indicated | P4: Inferred | Q4: Product | R4: Measured | S4: Indicated | T4: Measured & Indicated | U4: Inferred | V4: Total | W4: Proven | X4: Probable | Y4: Total | Z4: Proven | AA4: Probable | AB4: Total | AC4: Proven | AD4: Probable | AE4: Total | AF4: Source(s) | AH4: Notes
A5: Angel Island | B5: Nevada | C5: 37.7434 | D5: -117.52684 | E5: Feasibility Complete | F5: Clay | G5: Open pit | H5: Direct lithium extraction | I5: 858.26 | J5: 280.33 | K5: =SUM(I5:J5) -> 1138.59 | L5: 187.28 | M5: 990 | N5: 891 | O5: 966 | P5: 820 | Q5: LCE | R5: 4.53 | S5: 1.329 | T5: =SUM(R5:S5) -> 5.859 | U5: 0.817 | V5: =SUM(R5,S5,U5) -> 6.676 | W5: 266.39 | X5: 21.26 | Y5: =SUM(W5:X5) -> 287.65 | Z5: 1147 | AA5: 1174 | AB5: 1149 | AC5: 1.626 | AD5: 0.133 | AE5: =SUM(AC5:AD5) -> 1.759 | AF5: Feasibility Report 2024
A6: Basin | B6: Arizona | C6: 34.56688 | D6: -113.33924 | E6: Reserves Development | F6: Clay | G6: Open pit | I6: 20 | J6: 122 | K6: =SUM(I6:J6) -> 142 | L6: 506 | M6: 929 | N6: 860 | P6: 810 | Q6: LCE | R6: 0.099 | S6: 0.56 | T6: =SUM(R6:S6) -> 0.659 | U6: 2.175 | V6: =SUM(R6,S6,U6) -> 2.834 | AF6: Technical Report 2024
A7: Big Sandy | B7: Arizona | C7: 34.70922 | D7: -113.56947 | E7: Exploration | F7: Sediment-contained | G7: Open pit | J7: 14.6 | K7: =SUM(I7:J7) -> 14.6 | L7: 32.5 | N7: 1940 | P7: 178 | Q7: LCE | S7: 0.1509 | T7: =SUM(R7:S7) -> 0.1509 | U7: 0.1699 | V7: =SUM(R7,S7,U7) -> 0.3208 | AF7: Arizona Lithium website
A8: Black Rock Geothermal | B8: California | C8: 33.168306 | D8: -115.62539 | E8: Reserves Development | F8: Geothermal brine | G8: Pumping | H8: Direct lithium extraction | AF8: Technical Memorandum 2021 | AG8: California Energy Commission Website | AH8: 87 MW gross, 77 MW net
A9: Bonnie Claire Open Pit | B9: Nevada | C9: 37.21703 | D9: -117.0349 | E9: Prefeas/Scoping | F9: Sediment-contained | G9: Open pit | H9: Calcine leaching | J9: 188.08 | K9: =SUM(I9:J9) -> 188.08 | L9: 451.1 | N9: 1074 | P9: 1106 | Q9: LCE | S9: 1.075 | T9: =SUM(R9:S9) -> 1.075 | U9: 2.655 | V9: =SUM(R9,S9,U9) -> 3.73 | AF9: Technical Report 2024
A10: Bonnie Claire Borehole | B10: Nevada | C10: 37.21703 | D10: -117.0349 | E10: Prefeas/Scoping | F10: Sediment-contained | G10: Borehole mining | H10: Calcine leaching | J10: 275.85 | K10: =SUM(I10:J10) -> 275.85 | L10: 1561.06 | N10: 3519 | P10: 3085 | Q10: LCE | S10: 5.167 | T10: =SUM(R10:S10) -> 5.167 | U10: 25.634 | V10: =SUM(R10,S10,U10) -> 30.801 | AF10: Technical Report 2024
A11: Clayton Northeast (Pure Energy Minerals) | B11: Nevada | C11: 37.73454 | D11: -117.61009 | E11: Target Outline | F11: Brine | G11: Pumping | H11: Direct lithium extraction | L11: =5524000000/1000000 -> 5524 | P11: 123 | Q11: LCE | U11: 0.2177 | V11: =SUM(R11,S11,U11) -> 0.2177 | AF11: Preliminary Economic Assessment 2018 | AH11: Ore deposit is brine volume in Mm3
A12: Clayton Ridge | B12: Nevada | C12: 37.77667 | D12: -117.47683 | E12: Reserves Development | F12: Clay | G12: Open pit | I12: 379.14474 | J12: 141.32542 | K12: =SUM(I12:J12) -> 520.47015 | L12: 70.455712 | O12: 1000 | Q12: LCE | R12: 1.645 | S12: 0.602844 | T12: =SUM(R12:S12) -> 2.247844 | U12: 0.299325 | V12: =SUM(R12,S12,U12) -> 2.547169 | AF12: Authium website
A13: Hell's Kitchen | B13: California | C13: 33.227315 | D13: -115.58071 | E13: Construction Started | F13: Geothermal brine | G13: Pumping | H13: Direct lithium extraction | M13: 219 | N13: 219 | Q13: LHE | R13: 0.6 | S13: 1.1 | T13: =SUM(R13:S13) -> 1.7 | V13: =SUM(R13,S13,U13) -> 1.7 | AA13: 217 | AB13: 1149 | AD13: 0.9 | AE13: =SUM(AC13:AD13) -> 0.9 | AF13: CTR Brochure | AG13: Project Update 2025 | AH13: Stage 1 Power Generation: 50 MW
A14: Horizon | B14: Nevada | C14: 38.05571 | D14: -117.35221 | E14: Reserves Development | F14: Clay | J14: 372.845 | K14: =SUM(I14:J14) -> 372.845 | L14: 2453.963 | N14: 669 | P14: 680 | Q14: LCE | S14: 1.32 | T14: =SUM(R14:S14) -> 1.32 | U14: 8.879 | V14: =SUM(R14,S14,U14) -> 10.199 | AF14: Technical Report 2024
A15: Kings Mountain | B15: North Carolina | C15: 35.22361 | D15: -81.34778 | E15: Prefeas/Scoping | F15: Hardrock | G15: Open pit | H15: Acid leaching | J15: 46.816 | K15: =SUM(I15:J15) -> 46.816 | L15: 42.869 | N15: 1.37 | O15: 1.37 | P15: 1.1 | Q15: LHE | S15: =K15*(O15/100)*(lhe/li2o) -> 1.02716 | T15: =SUM(R15:S15) -> 1.02716 | U15: =(L15*(P15/100)*(lhe/li2o)) -> 0.75519528 | V15: =SUM(R15,S15,U15) -> 1.7823553 | AF15: Albemarle Resource Estimate 2021 | AH15: Lithium content % is in % Li2O
A16: Lithium Nevada (Thacker Pass) | B16: Nevada | C16: 41.70883 | D16: -118.06978 | E16: Construction Started | F16: Sediment-contained | G16: Open pit, pumping | H16: Acid leaching, evaporation | J16: 534.7 | K16: =SUM(I16:J16) -> 534.7 | L16: 992.5 | M16: 2450 | N16: 1850 | O16: 2070 | P16: 1870 | Q16: LCE | R16: 7 | S16: 9.1 | T16: =SUM(R16:S16) -> 16.1 | U16: 3 | V16: =SUM(R16,S16,U16) -> 19.1 | W16: 192.9 | X16: 24.4 | Y16: =SUM(W16:X16) -> 217.3 | Z16: 3180 | AA16: 3010 | AB16: 3160 | AC16: 3.3 | AD16: 0.4 | AE16: =SUM(AC16:AD16) -> 3.7 | AF16: Feasibility Report 2022
A17: Lone Mountain | B17: Nevada | C17: 38.12123 | D17: -117.42631 | E17: Exploration | F17: Clay | J17: 638 | K17: =SUM(I17:J17) -> 638 | L17: 857 | N17: 774 | O17: 789 | P17: 783 | Q17: LCE | S17: 2.627 | T17: =SUM(R17:S17) -> 2.627 | U17: 3.597 | V17: =SUM(R17,S17,U17) -> 6.224 | AF17: Austroid website | AG17: MRE Announcement 2024
A18: McDermitt JLL | B18: Oregon | C18: 42.04162 | D18: -118.05924 | E18: Prefeas/Scoping | F18: Clay | G18: Open pit | J18: 1470 | K18: =SUM(I18:J18) -> 1470 | L18: 1540 | N18: 1420 | P18: 1270 | Q18: LCE | S18: 11.1 | T18: =SUM(R18:S18) -> 11.1 | U18: 10.4 | V18: =SUM(R18,S18,U18) -> 21.5 | AF18: Prefeasbility Study 2024
A19: McGee | B19: Nevada | C19: 37.71199 | D19: -117.54459 | E19: Reserves Development | F19: Clay | H19: Acid leaching | J19: 320 | K19: =SUM(I19:J19) -> 320 | L19: 157 | N19: 803 | P19: 865 | Q19: LCE | S19: 1.369 | T19: =SUM(R19:S19) -> 1.369 | U19: 0.723 | V19: =SUM(R19,S19,U19) -> 2.092 | AF19: Technical Report 2022
A20: Paradox | B20: Utah | C20: 38.5685 | D20: -109.73452 | E20: Feasibility Complete | F20: Oil-field brine | G20: Pumping | H20: Direct lithium extraction | J20: 562 | K20: =SUM(I20:J20) -> 562 | L20: 1954 | N20: 123 | P20: 109 | Q20: LCE | S20: 0.367 | T20: =SUM(R20:S20) -> 0.367 | U20: 1.138 | V20: =SUM(R20,S20,U20) -> 1.505 | AF20: Anson Resources website | AH20: Ore deposit is brine tonnage in Mt
A21: Piedmont Carolina | B21: North Carolina | C21: 35.39446 | D21: -81.28475 | E21: Feasibility Complete | F21: Hardrock | G21: Open pit | H21: Chemical flotation | J21: 28.2 | K21: =SUM(I21:J21) -> 28.2 | L21: 15.9 | N21: 1.11 | P21: 1.02 | Q21: LCE | S21: 0.774 | T21: =SUM(R21:S21) -> 0.774 | U21: 0.401 | V21: =SUM(R21,S21,U21) -> 1.175 | X21: 18.26 | Y21: =SUM(W21:X21) -> 18.26 | AA21: 1.1 | AD21: 0.495 | AF21: Technical Report 2021 | AH21: Lithium content % is in % Li2O
A22: Rhyolite Ridge | B22: Nevada | C22: 37.81491 | D22: -117.85253 | E22: Construction Planned | F22: Clay | G22: Open pit | H22: Acid leaching | I22: =64.38+68.713+19.191 -> 152.284 | J22: =87.372+145.061+29.066 -> 261.499 | K22: =SUM(I22:J22) -> 413.783 | L22: =26.873+60.199+9.518 -> 96.59 | M22: =AVERAGE(1752,1257,2203) -> 1737.3333 | N22: =AVERAGE(1551,1196,2112) -> 1619.6667 | O22: =AVERAGE(M22:N22) -> 1678.5 | P22: =AVERAGE(1554,1249,1789) -> 1530.6667 | Q22: LCE | R22: =0.6+0.46+0.225 -> 1.285 | S22: =0.721+0.923+0.327 -> 1.971 | T22: =SUM(R22:S22) -> 3.256 | U22: =0.222+0.4+0.091 -> 0.713 | V22: =SUM(R22,S22,U22) -> 3.969 | W22: =(39.428+46.321)*(ton/ston) -> 77.790277 | X22: =(51.812+109.065)*(ton/ston) -> 145.94533 | Y22: =SUM(W22:X22) -> 223.73561 | Z22: =AVERAGE(1823,1358) -> 1590.5 | AA22: =AVERAGE(1632,1425) -> 1528.5 | AB22: 1465 | AC22: =(0.383+0.335)*(ton/ston) -> 0.65135942 | AD22: =(0.45+0.755)*(ton/ston) -> 1.0931589 | AE22: =SUM(AC22:AD22) -> 1.7445183 | AF22: Technical Report 2021 | AG22: Ioneer website
A23: Silver Peak | B23: Nevada | C23: 37.77544 | D23: -117.57931 | E23: Operating | F23: Brine | G23: Pumping | H23: Evaporation | I23: 10 | J23: 25 | K23: =SUM(I23:J23) -> 35 | L23: 63 | M23: 153 | N23: 144 | O23: 146 | P23: 121 | Q23: LCE | U23: 0.191628 | V23: =SUM(R23,S23,U23) -> 0.191628 | Z23: 94 | AA23: 95 | AB23: 95 | AC23: =0.12*(lce/li) -> 0.63876 | AD23: =0.563*(lce/li) -> 2.996849 | AE23: =SUM(AC23:AD23) -> 3.635609 | AF23: Technical Report 2023 | AG23: Albemarle Resource Estimate 2021 | AH23: Product reserves originally reported as contained lithium
A24: South West Arkansas | B24: Arkansas | C24: 33.23241 | D24: -93.55148 | E24: Feasibility Complete | F24: Oil-field brine | G24: Pumping | H24: Direct lithium extraction | L24: 343 | N24: 4460 | P24: 4050 | Q24: LHE | S24: 1.43 | T24: =SUM(R24:S24) -> 1.43 | U24: 0.392 | V24: =SUM(R24,S24,U24) -> 1.822 | AF24: Prefeasbility Study 2023 | AG24: Standard Lithium website
A25: TLC | B25: Nevada | C25: 38.15412 | D25: -117.27217 | E25: Prefeas/Scoping | F25: Clay | G25: Open pit | H25: Acid leaching | I25: 426.377 | J25: 1105.8582 | K25: =SUM(I25:J25) -> 1532.2352 | L25: 362.874 | M25: 932 | N25: 898 | O25: 919 | P25: 912 | Q25: LCE | R25: 3.374727 | S25: 2.023022 | T25: =SUM(R25:S25) -> 5.397749 | U25: 1.741795 | V25: =SUM(R25,S25,U25) -> 7.139544 | AF25: Preliminary Economic Assessment 2023
A26: Tonopah Flats | B26: Nevada | C26: 38.1099 | D26: -117.3479 | E26: Exploration | F26: Clay | G26: Open pit | H26: Acid leaching | I26: 721 | J26: 2439 | K26: =SUM(I26:J26) -> 3160 | L26: 3160 | M26: 720 | N26: 565 | O26: 596 | P26: 550 | Q26: LHE | R26: 3.06 | S26: 8.34 | T26: =SUM(R26:S26) -> 11.4 | U26: 9.75 | V26: =SUM(R26,S26,U26) -> 21.15 | AF26: Resource Estimate 2024
A27: West Tonopah | B27: Nevada | C27: 38.09889 | D27: -117.3087 | E27: Reserves Development | F27: Clay | G27: Open pit | J27: 65.3 | K27: =SUM(I27:J27) -> 65.3 | L27: 118.674 | M27: 609 | P27: 709 | Q27: LCE | S27: 0.212 | T27: =SUM(R27:S27) -> 0.212 | U27: 0.445 | V27: =SUM(R27,S27,U27) -> 0.657 | AF27: Technical Report 2023 | AH27: Inferred is weighted average of west and east resources
A28: Zeus | B28: Nevada | C28: 37.77485 | D28: -117.50934 | E28: Prefeas/Scoping | F28: Clay | G28: Open pit | H28: Acid leaching | J28: 564 | K28: =SUM(I28:J28) -> 564 | L28: 287 | M28: 860 | N28: 957 | P28: 861 | Q28: LCE | R28: 0.532 | S28: 4.63 | T28: =SUM(R28:S28) -> 5.162 | U28: 1.86 | V28: =SUM(R28,S28,U28) -> 7.022 | AF28: Technical Report 2024 | AG28: Iyer and Kelly 2023
A30: Table S4B. Annual Production for Proposed Sites with Given Annual Production
A31: Proposed Site Name | B31: Product | C31: Annual Production (tons/yr) | D31: Source(s)
A32: Angel Island | B32: LCE | C32: 34000 | D32: Feasibility Report 2024
A33: Black Rock Geothermal | B33: LCE | C33: 90000 | D33: Technical Memorandum 2021
A34: Bonnie Claire | B34: LCE | C34: 32300 | D34: Preliminary Economic Assessment 2022
A35: Clayton Northeast (Pure Energy Minerals) | B35: LCE | C35: 10000 | D35: Preliminary Economic Assessment 2018
A36: Hell's Kitchen | B36: LHE | C36: 25000 | D36: Project Update 2025
A37: Kings Mountain | B37: SC | C37: 381018 | D37: Albemarle Resource Estimate 2021
A38: Lithium Nevada (Thacker Pass) | B38: LCE | C38: 160000 | D38: Lithium Americas Website
A39: McDermitt JLL | B39: LCE | C39: 44300 | D39: Prefeasbility Study 2024
A40: Paradox | B40: LCE | C40: 13074 | D40: Anson Resources website
A41: Piedmont Carolina | B41: LHE | C41: 33000 | D41: Technical Report 2021
A42: Rhyolite Ridge | B42: LHE | C42: 21953.897 | D42: Technical Report 2021
...

Sheet 5. Proposed Mine Water Data
A2: Table S5A. Proposed Mine Water Use
A3: Proposed Site Name | B3: Deposit Type | C3: Mine Type | D3: Extraction Process | E3: Provided Water Use | F3: Units | G3: Provided Water Use (m3/yr) | H3: Provided Water Use (Mm3/yr) | I3: Source(s) | J3: Notes
A4: Angel Island | B4: Clay | C4: Open pit | D4: Direct lithium extraction | E4: 224.1 | F4: m3/hr | G4: =E4*(hr/yr) -> 1963116 | H4: =G4/1000000 -> 1.963116 | I4: Feasibility Report 2024
A5: Basin | B5: Clay | C5: Open pit | H5: =G5/1000000 -> 0
A6: Big Sandy | B6: Sediment-contained | C6: Open pit | H6: =G6/1000000 -> 0
A7: Black Rock Geothermal | B7: Geothermal brine | C7: Pumping | D7: Direct lithium extraction | E7: 13165 | F7: acre-ft/yr | G7: =E7*(cubicm/acreft) -> 16238772 | H7: =G7/1000000 -> 16.238772 | I7: Draft Project Environmental Impact Review 2024 | J7: For three plants in the area
A8: Bonnie Claire Open Pit | B8: Sediment-contained | C8: Open pit | D8: Calcine leaching | E8: 5382497 | F8: m3/hr | G8: 5382497 | H8: =G8/1000000 -> 5.382497 | I8: Preliminary Economic Assessment 2022 | J8: Water consumption is for both Bonnie Claire projects
A9: Bonnie Claire Borehole | B9: Sediment-contained | C9: Borehole mining | D9: Calcine leaching | H9: =G9/1000000 -> 0
A10: Clayton Northeast (Pure Energy Minerals) | B10: Brine | C10: Pumping | D10: Direct lithium extraction | E10: =860000 -> 860000 | F10: m3/yr | G10: =E10 -> 860000 | H10: =G10/1000000 -> 0.86 | I10: Preliminary Economic Assessment 2018
A11: Clayton Ridge | B11: Clay | C11: Open pit | H11: =G11/1000000 -> 0
A12: Hell's Kitchen | B12: Geothermal brine | C12: Pumping | D12: Direct lithium extraction | E12: 6500 | F12: acre-ft/yr | G12: =E12*(cubicm/acreft) -> 8017624 | H12: =G12/1000000 -> 8.017624 | I12: Draft Project Environmental Impact Review 2024
A13: Horizon | B13: Clay | H13: =G13/1000000 -> 0
A14: Kings Mountain | B14: Hardrock | C14: Open pit | D14: Acid leaching | H14: =G14/1000000 -> 0
A15: Thacker Pass | B15: Clay, brine | C15: Open pit, pumping | D15: Acid leaching, evaporation | E15: =(10.6*1000000)+(18.8*1000000) -> 29400000 | F15: m3/yr | G15: =E15 -> 29400000 | H15: =G15/1000000 -> 29.4 | I15: Feasibility Report 2022
A16: Lone Mountain | B16: Clay | H16: =G16/1000000 -> 0
A17: McDermitt JLL | B17: Clay | C17: Open pit | H17: =G17/1000000 -> 0
A18: McGee | B18: Clay | C18: Open pit | D18: Acid leaching | H18: =G18/1000000 -> 0
A19: Paradox | B19: Oil-field brine | C19: Pumping | D19: Direct lithium extraction | E19: =AVERAGE(200,250) -> 225 | F19: acre-ft/yr | G19: =E19*(cubicm/acreft) -> 277533.14 | H19: =G19/1000000 -> 0.27753314 | I19: Corporate Presentation 2024
A20: Piedmont Carolina | B20: Hardrock | C20: Open pit | D20: Chemical flotation | E20: 2106 | F20: m3/day | G20: =E20*(day/yr) -> 768690 | H20: =G20/1000000 -> 0.76869 | I20: Technical Report 2021
A21: Rhyolite Ridge | B21: Clay | C21: Open pit | D21: Acid leaching | E21: 2150 | F21: gpm | G21: =E21*(cubicm/gal)*(min/yr) -> 4277667.6 | H21: =G21/1000000 -> 4.2776676 | I21: Technical Report 2021
A22: Silver Peak | B22: Brine | C22: Pumping | D22: Evaporation | E22: 24669600 | F22: m3/yr | G22: =E22 -> 24669600 | H22: =G22/1000000 -> 24.6696 | I22: Technical Report 2023
A23: South West Arkansas | B23: Oil-field brine | C23: Pumping | D23: Direct lithium extraction | E23: 413 | F23: m3/hr | G23: =E23*(hr/yr) -> 3617880 | H23: =G23/1000000 -> 3.61788 | I23: Prefeasbility Study 2023
A24: TLC | B24: Clay | C24: Open pit | D24: Acid leaching | E24: ='6. Proposed Mine LCI Values'!H35*'6. Proposed Mine LCI Values'!H36 -> 6688000 | F24: m3/yr | G24: =E24 -> 6688000 | H24: =G24/1000000 -> 6.688 | I24: Preliminary Economic Assessment 2023
A25: Tonopah Flats | B25: Clay | C25: Open pit | D25: Acid leaching | E25: 649.87163 | F25: m3/hr | G25: =E25*(hr/yr) -> 5692875.5 | H25: =G25/1000000 -> 5.6928755 | I25: Resource Estimate 2024
A26: West Tonopah | B26: Clay | C26: Open pit | H26: =G26/1000000 -> 0
A27: Zeus | B27: Clay | C27: Open pit | D27: Acid leaching | H27: =G27/1000000 -> 0 | I27: Technical Report 2024

Sheet 6. Proposed Mine LCI Values
A2: Table S6A. Life Cycle Inventory (LCI) water consumption data from technical reports of proposed mines that report water consumption and annual production
A3: Site Name | B3: State | C3: County | D3: Deposit Type | E3: Mining Method | F3: Extraction Method | G3: Input | H3: Input value | I3: Input unit
A4: Angel Island | B4: Nevada | C4: Esmeralda | D4: Clay | E4: Open pit | F4: Direct lithium extraction | G4: Net water use | H4: ='5. Proposed Mine Water Data'!G4 -> 1963116 | I4: m3/yr
G5: LCE production | H5: ='4. Proposed Mine LOM & Resource'!C32 -> 34000 | I5: t/yr
A6: Black Rock Geothermal | B6: California | C6: Imperial | D6: Geothermal brine | E6: Pumping | F6: Direct lithium extraction | G6: Net water use | H6: 13165 | I6: acre-ft/yr
G7: LCE production | H7: 90000 | I7: t/yr
A8: Bonnie Claire | B8: Nevada | C8: Nye | D8: Sediment-contained | E8: Open pit/borehole | F8: Calcine leaching | G8: Net water use | H8: 5382497 | I8: m3/yr
G9: LCE production | H9: 32300 | I9: t/yr
A10: Clayton Northeast (Pure Energy Minerals) | B10: Nevada | C10: Esmeralda | D10: Brine | E10: Pumping | F10: Direct lithium extraction | G10: Brine | H10: 1250 | I10: m3/hr
G11: Groundwater extracted | H11: =23.52*1000000 -> 23520000 | I11: m3/yr
G12: Groundwater returned | H12: =22.66*1000000 -> 22660000 | I12: m3/yr
G13: Net water use | H13: =H11-H12 -> 860000 | I13: m3/yr
G14: LCE production | H14: 10000 | I14: t/yr
A15: Hell's Kitchen | B15: California | C15: Imperial | D15: Geothermal brine | E15: Pumping | F15: Direct lithium extraction | G15: Net water use | H15: 6500 | I15: acre-ft/yr
G16: LCE production | H16: =25000*(lce/lhe) -> 38594.838 | I16: t/yr
A17: Lithium Nevada Thacker Pass | B17: Nevada | C17: Humboldt | D17: Clay, brine | E17: Open pit, pumping | F17: Acid leaching, evaporation | G17: Process net water use | H17: =831+1385 -> 2216 | I17: m3/hr
G18: Extraction net water use | H18: =250+750 -> 1000 | I18: m3/hr
G19: LCE production | H19: 160000 | I19: t/yr
A20: Paradox | B20: Utah | C20: Grand | D20: Oil-field brine | E20: Pumping | F20: Direct lithium extraction | G20: Process net water use | H20: =AVERAGE(200,250) -> 225 | I20: acre-ft/yr | J20: *average between 200-250
G21: LCE production | H21: ='4. Proposed Mine LOM & Resource'!C40 -> 13074 | I21: t/yr
A22: Piedmont Carolina | B22: North Carolina | C22: Gaston | D22: Hardrock | E22: Open pit | F22: Chemical flotation | G22: Ore feed | H22: 1900000 | I22: t/yr
G23: Spodumene concentrate | H23: 230000 | I23: t/yr
G24: Mine dewatering | H24: 1400 | I24: gpm | J24: *Not included in total calculation. Water goes to treatment plant and is released
G25: Process net water use | H25: 2106 | I25: m3/day
G26: LHE production | H26: 33000 | I26: t/yr
A27: Rhyolite Ridge | B27: Nevada | C27: Esmeralda | D27: Clay | E27: Open pit | F27: Acid leaching | G27: Process net water use | H27: 2150 | I27: gpm
G28: LHE production | H28: =24200*(ton/ston) -> 21953.897 | I28: t/yr
A29: Silver Peak | B29: Nevada | C29: Esmeralda | D29: Brine | E29: Pumping | F29: Evaporation | G29: Process net water use | H29: 130 | I29: m3/t LCE
G30: Evapotranspiration | H30: 65898 | I30: m3/day | J30: *for 2022 production of 150,356 tons LCE
G31: LCE production | H31: 6000 | I31: t/yr
A32: South West Arkansas | B32: Arkansas | C32: Lafayette | D32: Oil-field brine | E32: Pumping | F32: Direct lithium extraction | G32: Brine | H32: 1800 | I32: m3/hr
G33: Net water use | H33: 413 | I33: m3/hr
G34: LHE production | H34: 30000 | I34: t/yr
A35: TLC | B35: Nevada | C35: Nye | D35: Clay | E35: Open pit | F35: Acid leaching | G35: Process net water use | H35: 0.76 | I35: m3/t ROM
G36: Run of Mill feed (ROM) | H36: =8.8*1000000 -> 8800000 | I36: t/yr
G37: LCE production | H37: 48000 | I37: t/yr
A38: Tonopah Flats | B38: Nevada | C38: Esmeralda | D38: Clay | E38: Open pit | F38: Acid leaching | G38: Process net water use | H38: =AVERAGE(17650,28250) -> 22950 | I38: ft3/hr | J38: *average of 17650 and 28250
G39: LHE production | H39: 33000 | I39: t/yr
A42: Table S6B. Life Cycle Inventory (LCI) water consumption data per ton of product
A43: Site Name | B43: State | C43: County | D43: Deposit Type | E43: Mining Method | F43: Extraction Method | G43: Input | H43: Input value | I43: Input unit | J43: Functional Unit
...

Sheet 7. Operating Mines Data
A2: Table S7A. Production and Water Consumption Data for Select Operating Mines
A3: Site Name (Operator) | B3: Country | C3: Deposit Type | D3: Extraction Process | E3: Product | F3: Category (units) | G3: 2022 | H3: 2023 | I3: 2024 | J3: Source
A4: Greenbushes (Talison) | B4: Australia | C4: Hardrock (spodumene) | D4: Chemical flotation | E4: Lithium mineral concentrate | F4: Production (tons) | G4: 1383425 | H4: 1491263 | I4: 1134580 | J4: Sustainability Report 2024
F5: Absolute percent change (%) | H5: =ABS((H4-G4)/G4) -> 0.077950015 | I5: =ABS((I4-H4)/H4) -> 0.23918182
F6: Water consumption (ML) | G6: 2484 | H6: 2749 | I6: 3201
F7: Absolute percent change (%) | H7: =ABS((H6-G6)/G6) -> 0.10668277 | I7: =ABS((I6-H6)/H6) -> 0.16442343
F8: Water consumption per product (m3/ton) (calculated) | G8: =(G6*1000000*(cubicm/liter))/G4 -> 1.7955437 | H8: =(H6*1000000*(cubicm/liter))/H4 -> 1.8434039 | I8: =(I6*1000000*(cubicm/liter))/I4 -> 2.8213083
F9: Absolute percent change (%) | H9: =ABS((H8-G8)/G8) -> 0.026654997 | I9: =ABS((I8-H8)/H8) -> 0.53048844
A10: Salar de Atacama (SQM) | B10: Chile | C10: Brine | D10: Evaporation | E10: LCE | F10: Production (tons) | G10: 120000 | H10: 180000 | I10: 201000 | J10: Annual Report 2024
F11: Absolute percent change (%) | H11: =ABS((H10-G10)/G10) -> 0.5 | I11: =ABS((I10-H10)/H10) -> 0.11666667
F12: Water consumption (m3) | G12: 29377645 | H12: 32615350 | I12: 29286059
F13: Absolute percent change (%) | H13: =ABS((H12-G12)/G12) -> 0.11020982 | I13: =ABS((I12-H12)/H12) -> 0.10207743
F14: Water consumption per product (m3/ton) (calculated) | G14: =G12/G10 -> 244.81371 | H14: =H12/H10 -> 181.19639 | I14: =I12/I10 -> 145.70179
F15: Absolute percent change (%) | H15: =ABS((H14-G14)/G14) -> 0.25986012 | I15: =ABS((I14-H14)/H14) -> 0.19589023
A16: Cauchari-Olaroz (Lithium Argentina) | B16: Argentina | C16: Brine | D16: DLE | E16: LCE | F16: Production (tons) | H16: 6000 | I16: 25400 | J16: Annual Report 2024 | K16: * Production began in 2023
F17: Absolute percent change (%) | I17: =ABS((I16-H16)/H16) -> 3.2333333 | K17: * Percent change represents a ramp-up, not changes at full-capacity
F18: Water consumption per product (m3/ton) (provided) | H18: =424.7-33 -> 391.7 | I18: =104.2-1.6 -> 102.6
F19: Absolute percent change (%) | I19: =ABS((I18-H18)/H18) -> 0.73806485

Sheet 8. Uncertainty Results
A2: Table S8A. Production and Water Consumption Percentiles by Proposed Mine
H3: Production estimate (tons/yr) | L3: Water consumption estimate (m3/yr)
A4: Proposed Site Name | B4: Deposit Type | C4: Mine Type | D4: Extraction Process | E4: HUC8 ID | F4: HUC 8 Name | G4: Product | H4: Method | I4: p10 | J4: p50 | K4: p90 | L4: Method | M4: p10 | N4: p50 | O4: p90
A5: Angel Island | B5: Clay | C5: Open pit | D5: Direct lithium extraction | E5: 16060011 | F5: Ralston-Stone Cabin Valleys | G5: LCE | H5: =IF(ISNUMBER(MATCH(A5, '4. Proposed Mine LOM & Resource'!$A$32:$A$47, 0)), "+/- 20%", "Regression") -> +/- 20% | I5: 31122.756 | J5: 33986.056 | K5: 36917.164 | L5: +/- 20% | M5: 1796217.8 | N5: 1964146 | O5: 2128839.6
A6: Basin | B6: Clay | C6: Open pit | E6: 15030202 | F6: Burro | G6: LCE | H6: =IF(ISNUMBER(MATCH(A6, '4. Proposed Mine LOM & Resource'!$A$32:$A$47, 0)), "+/- 20%", "Regression") -> Regression | I6: 4371.1455 | J6: 15819.637 | K6: 59745.559 | L6: Literature Estimate | M6: 366842.57 | N6: 1927238.7 | O6: 9736611.9
A7: Big Sandy | B7: Sediment-contained | C7: Open pit | E7: 15030201 | F7: Big Sandy | G7: LCE | H7: =IF(ISNUMBER(MATCH(A7, '4. Proposed Mine LOM & Resource'!$A$32:$A$47, 0)), "+/- 20%", "Regression") -> Regression | I7: 2791.3071 | J7: 9479.8782 | K7: 33828.581 | L7: Literature Estimate | M7: 234256.74 | N7: 1154893 | O7: 5512974.9
A8: Black Rock Geothermal | B8: Geothermal brine | C8: Pumping | D8: Direct lithium extraction | E8: 18100204 | F8: Salton Sea | G8: LCE | H8: =IF(ISNUMBER(MATCH(A8, '4. Proposed Mine LOM & Resource'!$A$32:$A$47, 0)), "+/- 20%", "Regression") -> +/- 20% | I8: 82349.379 | J8: 90075.272 | K8: 97544.257 | L8: +/- 20% | M8: 14866480 | N8: 16255793 | O8: 17610505
A9: Bonnie Claire | B9: Sediment-contained | C9: Open pit | D9: Calcine leaching | E9: 16060013 | F9: Cactus-Sarcobatus Flats | G9: LCE | H9: =IF(ISNUMBER(MATCH(A9, '4. Proposed Mine LOM & Resource'!$A$32:$A$47, 0)), "+/- 20%", "Regression") -> +/- 20% | I9: 29542.474 | J9: 32318.876 | K9: 35089.193 | L9: +/- 20% | M9: 4923485.5 | N9: 5371061.4 | O9: 5838965.4
A10: Clayton Northeast (Pure Energy Minerals) | B10: Brine | C10: Pumping | D10: Direct lithium extraction | E10: 16060011 | F10: Ralston-Stone Cabin Valleys | G10: LCE | H10: =IF(ISNUMBER(MATCH(A10, '4. Proposed Mine LOM & Resource'!$A$32:$A$47, 0)), "+/- 20%", "Regression") -> +/- 20% | I10: 9138.7424 | J10: 9997.5483 | K10: 10863.678 | L10: +/- 20% | M10: 787319.11 | N10: 860876.48 | O10: 932949.59
A11: Clayton Ridge | B11: Clay | C11: Open pit | E11: 16060011 | F11: Ralston-Stone Cabin Valleys | G11: LCE | H11: =IF(ISNUMBER(MATCH(A11, '4. Proposed Mine LOM & Resource'!$A$32:$A$47, 0)), "+/- 20%", "Regression") -> Regression | I11: 6335.4569 | J11: 24100.485 | K11: 95695.793 | L11: Literature Estimate | M11: 531694.8 | N11: 2936059 | O11: 15595348
A12: Hell's Kitchen | B12: Geothermal brine | C12: Pumping | D12: Direct lithium extraction | E12: 18100204 | F12: Salton Sea | G12: LHE | H12: =IF(ISNUMBER(MATCH(A12, '4. Proposed Mine LOM & Resource'!$A$32:$A$47, 0)), "+/- 20%", "Regression") -> +/- 20% | I12: 22856.123 | J12: 24973.624 | K12: 27140.141 | L12: +/- 20% | M12: 7332806.6 | N12: 8019624.4 | O12: 8690310.7
A13: Horizon | B13: Clay | E13: 16060003 | F13: Southern Big Smoky Valley | G13: LCE | H13: =IF(ISNUMBER(MATCH(A13, '4. Proposed Mine LOM & Resource'!$A$32:$A$47, 0)), "+/- 20%", "Regression") -> Regression | I13: 5409.8606 | J13: 20025.481 | K13: 77898.545 | L13: Literature Estimate | M13: 454015.36 | N13: 2439618.8 | O13: 12694967
A14: Kings Mountain | B14: Hardrock | C14: Open pit | D14: Acid leaching | E14: 3050105 | F14: Upper Broad | G14: LHE | H14: =IF(ISNUMBER(MATCH(A14, '4. Proposed Mine LOM & Resource'!$A$32:$A$47, 0)), "+/- 20%", "Regression") -> +/- 20% | I14: =348218.714035918*(1/'3. Literature LCI Values'!H127) -> 67223.69 | J14: =380719.317035847*(1/'3. Literature LCI Values'!H127) -> 73497.938 | K14: =412939.574460982*(1/'3. Literature LCI Values'!H127) -> 79718.065 | L14: Literature Estimate | M14: 5641658.7 | N14: 8953939.5 | O14: 12991490
A15: Lithium Nevada (Thacker Pass) | B15: Clay, brine | C15: Open pit, pumping | D15: Acid leaching, evaporation | E15: 16040201 | F15: Upper Quinn | G15: LCE | H15: =IF(ISNUMBER(MATCH(A15, '4. Proposed Mine LOM & Resource'!$A$32:$A$47, 0)), "+/- 20%", "Regression") -> +/- 20% | I15: 146385.59 | J15: 160054.18 | K15: 173613.79 | L15: +/- 20% | M15: 26931959 | N15: 29404297 | O15: 31956677
A16: Lone Mountain | B16: Clay | E16: 16060003 | F16: Southern Big Smoky Valley | G16: LCE | H16: =IF(ISNUMBER(MATCH(A16, '4. Proposed Mine LOM & Resource'!$A$32:$A$47, 0)), "+/- 20%", "Regression") -> Regression | I16: 6620.5761 | J16: 25395.614 | K16: 101942.65 | L16: Literature Estimate | M16: 555623.04 | N16: 3093839.1 | O16: 16613385
A17: McDermitt JLL | B17: Clay | C17: Open pit | E17: 16040201 | F17: Upper Quinn | G17: LCE | H17: =IF(ISNUMBER(MATCH(A17, '4. Proposed Mine LOM & Resource'!$A$32:$A$47, 0)), "+/- 20%", "Regression") -> +/- 20% | I17: 40487.002 | J17: 44374.143 | K17: 48156.192 | L17: Literature Estimate | M17: 3397817.8 | N17: 5405912.1 | O17: 7847916.4
A18: McGee | B18: Clay | C18: Open pit | D18: Acid leaching | E18: 16060011 | F18: Ralston-Stone Cabin Valleys | G18: LCE | H18: =IF(ISNUMBER(MATCH(A18, '4. Proposed Mine LOM & Resource'!$A$32:$A$47, 0)), "+/- 20%", "Regression") -> Regression | I18: 5468.9526 | J18: 20275.846 | K18: 78944.323 | L18: Literature Estimate | M18: 458974.57 | N18: 2470119.7 | O18: 12865395
A19: Paradox | B19: Oil-field brine | C19: Pumping | D19: Direct lithium extraction | E19: 14030005 | F19: Upper Colorado-Kane Springs | G19: LCE | H19: =IF(ISNUMBER(MATCH(A19, '4. Proposed Mine LOM & Resource'!$A$32:$A$47, 0)), "+/- 20%", "Regression") -> +/- 20% | I19: 11971.092 | J19: 13071.222 | K19: 14187.836 | L19: +/- 20% | M19: 253458.36 | N19: 277827.54 | O19: 301790.98
A20: Piedmont Carolina | B20: Hardrock | C20: Open pit | D20: Chemical flotation | E20: 3050102 | F20: South Fork Catawba | G20: LCE | H20: =IF(ISNUMBER(MATCH(A20, '4. Proposed Mine LOM & Resource'!$A$32:$A$47, 0)), "+/- 20%", "Regression") -> +/- 20% | I20: 30118.827 | J20: 32953.722 | K20: 35822.382 | L20: +/- 20% | M20: 700606.32 | N20: 767537.19 | O20: 833662.78
A21: Rhyolite Ridge | B21: Clay | C21: Open pit | D21: Acid leaching | E21: 16060010 | F21: Fish Lake-Soda Spring Valleys | G21: LCE | H21: =IF(ISNUMBER(MATCH(A21, '4. Proposed Mine LOM & Resource'!$A$32:$A$47, 0)), "+/- 20%", "Regression") -> +/- 20% | I21: 20124.505 | J21: 21932.814 | K21: 23777.942 | L21: +/- 20% | M21: 3907981.8 | N21: 4284302.1 | O21: 4647432.2
A22: Silver Peak | B22: Brine | C22: Pumping | D22: Evaporation | E22: 16060011 | F22: Ralston-Stone Cabin Valleys | G22: LCE | H22: =IF(ISNUMBER(MATCH(A22, '4. Proposed Mine LOM & Resource'!$A$32:$A$47, 0)), "+/- 20%", "Regression") -> +/- 20% | I22: 5474.876 | J22: 6003.1726 | K22: 6505.5457 | L22: +/- 20% | M22: 22551356 | N22: 24670307 | O22: 26821086
A23: South West Arkansas | B23: Oil-field brine | C23: Pumping | D23: Direct lithium extraction | E23: 11140205 | F23: Bodcau Bayou | G23: LHE | H23: =IF(ISNUMBER(MATCH(A23, '4. Proposed Mine LOM & Resource'!$A$32:$A$47, 0)), "+/- 20%", "Regression") -> +/- 20% | I23: 27459.712 | J23: 30024.933 | K23: 32572.002 | L23: +/- 20% | M23: 3314052.4 | N23: 3621992.4 | O23: 3935422.8
A24: TLC | B24: Clay | C24: Open pit | D24: Acid leaching | E24: 16060003 | F24: Southern Big Smoky Valley | G24: LCE | H24: =IF(ISNUMBER(MATCH(A24, '4. Proposed Mine LOM & Resource'!$A$32:$A$47, 0)), "+/- 20%", "Regression") -> +/- 20% | I24: 43873.663 | J24: 48000.509 | K24: 52014.236 | L24: +/- 20% | M24: 6122453.4 | N24: 6692140.1 | O24: 7257242.6
A25: Tonopah Flats | B25: Clay | C25: Open pit | D25: Acid leaching | E25: 16060003 | F25: Southern Big Smoky Valley | G25: LHE | H25: =IF(ISNUMBER(MATCH(A25, '4. Proposed Mine LOM & Resource'!$A$32:$A$47, 0)), "+/- 20%", "Regression") -> +/- 20% | I25: 30204.655 | J25: 33047.91 | K25: 35829.93 | L25: +/- 20% | M25: 5209753.4 | N25: 5701351.3 | O25: 6187033.9
A26: West Tonopah | B26: Clay | C26: Open pit | E26: 16060003 | F26: Southern Big Smoky Valley | G26: LCE | H26: =IF(ISNUMBER(MATCH(A26, '4. Proposed Mine LOM & Resource'!$A$32:$A$47, 0)), "+/- 20%", "Regression") -> Regression | I26: 3101.9588 | J26: 10671.217 | K26: 38556.901 | L26: Literature Estimate | M26: 260327.77 | N26: 1300028.7 | O26: 6283539.4
A27: Zeus | B27: Clay | C27: Open pit | D27: Acid leaching | E27: 16060011 | F27: Ralston-Stone Cabin Valleys | G27: LCE | H27: =IF(ISNUMBER(MATCH(A27, '4. Proposed Mine LOM & Resource'!$A$32:$A$47, 0)), "+/- 20%", "Regression") -> +/- 20% | I27: 29161.652 | J27: 31874.071 | K27: 34627.891 | L27: Literature Estimate | M27: 2447352.8 | N27: 3883081.8 | O27: 5643236.7
A30: Table S8B. Water Consumption Estimates by Deposit Type Uncertainty Analysis Results
C31: Water Consumption (m3/ton LCE)
A32: Deposit Type | B32: Extraction Process | C32: p10 | D32: p50 | E32: p90
A33: Brine | B33: Evaporation | C33: 84.679696 | D33: 192.95778 | E33: 348.77917
A34: Brine | B34: Direct lithium extraction | C34: 133.43887 | D34: 313.74772 | E34: 562.76974
A35: Hard rock | B35: Acid leaching | C35: 31 | D35: 54 | E35: 88
A36: Clay/Sediment-contained | B36: Acid leaching | C36: 83.92367 | D36: 121.82573 | E36: 162.96796
A37: Oil-field Brine | B37: Direct lithium extraction | C37: 42.680004 | D37: 70.481241 | E37: 98.418845
A39: Table S8C. WaSSI total water supply (Mgal/day) by HUC 8 uncertainty results
A40: Climate Model | B40: CNRM | H40: HadGEM2 | N40: IPSL | T40: MRI-CGCM3 | Z40: NorESM
A41: RCP | B41: RCP 4.5 | E41: RCP 8.5 | H41: RCP 4.5 | K41: RCP 8.5 | N41: RCP 4.5 | Q41: RCP 8.5 | T41: RCP 4.5 | W41: RCP 8.5 | Z41: RCP 4.5 | AC41: RCP 8.5
A42: HUC8 ID | B42: p10 | C42: p50 | D42: p90 | E42: p10 | F42: p50 | G42: p90 | H42: p10 | I42: p50 | J42: p90 | K42: p10 | L42: p50 | M42: p90 | N42: p10 | O42: p50 | P42: p90 | Q42: p10 | R42: p50 | S42: p90 | T42: p10 | U42: p50 | V42: p90 | W42: p10 | X42: p50 | Y42: p90 | Z42: p10 | AA42: p50 | AB42: p90 | AC42: p10 | AD42: p50 | AE42: p90
A43: 16060011 | B43: 36.983542 | C43: 53.576536 | D43: 80.006728 | E43: 34.42204 | F43: 50.10924 | G43: 75.165521 | H43: 32.998711 | I43: 42.108868 | J43: 54.602209 | K43: 30.69332 | L43: 38.935073 | M43: 51.761639 | N43: 28.770185 | O43: 33.002939 | P43: 38.918918 | Q43: 32.926498 | R43: 45.191381 | S43: 64.744586 | T43: 30.569517 | U43: 37.393595 | V43: 47.973778 | W43: 34.292179 | X43: 48.777653 | Y43: 72.614003 | Z43: 37.240272 | AA43: 59.198518 | AB43: 94.605852 | AC43: 43.782502 | AD43: 84.642613 | AE43: 150.74858
A44: 15030202 | B44: 41.867905 | C44: 69.173541 | D44: 98.418268 | E44: 42.99279 | F44: 82.145039 | G44: 130.89457 | H44: 46.68448 | I44: 95.981527 | J44: 171.28965 | K44: 34.377711 | L44: 64.228706 | M44: 105.48083 | N44: 37.552502 | O44: 71.278185 | P44: 122.11276 | Q44: 25.850094 | R44: 42.621283 | S44: 65.203657 | T44: 34.741721 | U44: 64.963436 | V44: 104.69321 | W44: 42.725163 | X44: 67.68807 | Y44: 98.437228 | Z44: 29.341248 | AA44: 52.65392 | AB44: 83.403831 | AC44: 41.321261 | AD44: 83.147187 | AE44: 145.80377
...

Sheet 9. Net Water Avail Vis
A2: Table S9A. CNRM Net Water Availability
A4: By HUC8 watershed, based on mine alphabetical order
B5: RSCV | F5: BUR | J5: BS | N5: SS | R5: CSF | V5: MOJ | Z5: SBSV | AD5: UB | AH5: UQ | AL5: UCKS | AP5: SFC | AT5: FLSSV | AX5: BB
B6: 16060011 | F6: 15030202 | J6: 15030201 | N6: 18100204 | R6: 16060013 | V6: 18090208 | Z6: 16060003 | AD6: 3050105 | AH6: 16040201 | AL6: 14030005 | AP6: 3050102 | AT6: 16060010 | AX6: 11140205
B7: RCP 4.5 SSP1 | C7: RCP 8.5 SSP2 | D7: RCP 8.5 SSP3 | E7: RCP 8.5 SSP5 | F7: RCP 4.5 SSP1 | G7: RCP 8.5 SSP2 | H7: RCP 8.5 SSP3 | I7: RCP 8.5 SSP5 | J7: RCP 4.5 SSP1 | K7: RCP 8.5 SSP2 | L7: RCP 8.5 SSP3 | M7: RCP 8.5 SSP5 | N7: RCP 4.5 SSP1 | O7: RCP 8.5 SSP2 | P7: RCP 8.5 SSP3 | Q7: RCP 8.5 SSP5 | R7: RCP 4.5 SSP1 | S7: RCP 8.5 SSP2 | T7: RCP 8.5 SSP3 | U7: RCP 8.5 SSP5 | V7: RCP 4.5 SSP1 | W7: RCP 8.5 SSP2 | X7: RCP 8.5 SSP3 | Y7: RCP 8.5 SSP5 | Z7: RCP 4.5 SSP1 | AA7: RCP 8.5 SSP2 | AB7: RCP 8.5 SSP3 | AC7: RCP 8.5 SSP5 | AD7: RCP 4.5 SSP1 | AE7: RCP 8.5 SSP2 | AF7: RCP 8.5 SSP3 | AG7: RCP 8.5 SSP5 | AH7: RCP 4.5 SSP1 | AI7: RCP 8.5 SSP2 | AJ7: RCP 8.5 SSP3 | AK7: RCP 8.5 SSP5 | AL7: RCP 4.5 SSP1 | AM7: RCP 8.5 SSP2 | AN7: RCP 8.5 SSP3 | AO7: RCP 8.5 SSP5 | AP7: RCP 4.5 SSP1 | AQ7: RCP 8.5 SSP2 | AR7: RCP 8.5 SSP3 | AS7: RCP 8.5 SSP5 | AT7: RCP 4.5 SSP1 | AU7: RCP 8.5 SSP2 | AV7: RCP 8.5 SSP3 | AW7: RCP 8.5 SSP5 | AX7: RCP 4.5 SSP1 | AY7: RCP 8.5 SSP2 | AZ7: RCP 8.5 SSP3 | BA7: RCP 8.5 SSP5
A8: p10 | B8: =VLOOKUP(B$6,'8. Uncertainty Results'!$B$223:$N$235,11,FALSE) -> -47.925476 | C8: =VLOOKUP(B$6,'8. Uncertainty Results'!$B$293:$N$305,11,FALSE) -> -55.898533 | D8: =VLOOKUP(B$6,'8. Uncertainty Results'!$B$364:$N$376,11,FALSE) -> -54.233805 | E8: =VLOOKUP(B$6,'8. Uncertainty Results'!$B$434:$N$446,11,FALSE) -> -57.603329 | F8: =VLOOKUP(F$6,'8. Uncertainty Results'!$B$223:$N$235,11,FALSE) -> -137.97431 | G8: =VLOOKUP(F$6,'8. Uncertainty Results'!$B$293:$N$305,11,FALSE) -> -97.529141 | H8: =VLOOKUP(F$6,'8. Uncertainty Results'!$B$364:$N$376,11,FALSE) -> -83.630003 | I8: =VLOOKUP(F$6,'8. Uncertainty Results'!$B$434:$N$446,11,FALSE) -> -113.66207 | J8: =VLOOKUP(J$6,'8. Uncertainty Results'!$B$223:$N$235,11,FALSE) -> -86.6769 | K8: =VLOOKUP(J$6,'8. Uncertainty Results'!$B$293:$N$305,11,FALSE) -> -45.586065 | L8: =VLOOKUP(J$6,'8. Uncertainty Results'!$B$364:$N$376,11,FALSE) -> -29.883434 | M8: =VLOOKUP(J$6,'8. Uncertainty Results'!$B$434:$N$446,11,FALSE) -> -60.868897 | N8: =VLOOKUP(N$6,'8. Uncertainty Results'!$B$223:$N$235,11,FALSE) -> -389.82744 | O8: =VLOOKUP(N$6,'8. Uncertainty Results'!$B$293:$N$305,11,FALSE) -> -1468.7587 | P8: =VLOOKUP(N$6,'8. Uncertainty Results'!$B$364:$N$376,11,FALSE) -> -1464.2888 | Q8: =VLOOKUP(N$6,'8. Uncertainty Results'!$B$434:$N$446,11,FALSE) -> -1487.6343 | R8: =VLOOKUP(R$6,'8. Uncertainty Results'!$B$223:$N$235,11,FALSE) -> -29.882623 | S8: =VLOOKUP(R$6,'8. Uncertainty Results'!$B$293:$N$305,11,FALSE) -> -40.003379 | T8: =VLOOKUP(R$6,'8. Uncertainty Results'!$B$364:$N$376,11,FALSE) -> -38.893615 | U8: =VLOOKUP(R$6,'8. Uncertainty Results'!$B$434:$N$446,11,FALSE) -> -42.51057 | V8: =VLOOKUP(V$6,'8. Uncertainty Results'!$B$223:$N$235,11,FALSE) -> -862.67602 | W8: =VLOOKUP(V$6,'8. Uncertainty Results'!$B$293:$N$305,11,FALSE) -> -1148.1619 | X8: =VLOOKUP(V$6,'8. Uncertainty Results'!$B$364:$N$376,11,FALSE) -> -1062.4271 | Y8: =VLOOKUP(V$6,'8. Uncertainty Results'!$B$434:$N$446,11,FALSE) -> -1255.1264 | Z8: =VLOOKUP(Z$6,'8. Uncertainty Results'!$B$223:$N$235,11,FALSE) -> -27.863979 | AA8: =VLOOKUP(Z$6,'8. Uncertainty Results'!$B$293:$N$305,11,FALSE) -> -35.516203 | AB8: =VLOOKUP(Z$6,'8. Uncertainty Results'!$B$364:$N$376,11,FALSE) -> -34.412659 | AC8: =VLOOKUP(Z$6,'8. Uncertainty Results'!$B$434:$N$446,11,FALSE) -> -36.626251 | AD8: =VLOOKUP(AD$6,'8. Uncertainty Results'!$B$223:$N$235,11,FALSE) -> 2232.013 | AE8: =VLOOKUP(AD$6,'8. Uncertainty Results'!$B$293:$N$305,11,FALSE) -> 2241.4245 | AF8: =VLOOKUP(AD$6,'8. Uncertainty Results'!$B$364:$N$376,11,FALSE) -> 2254.1925 | AG8: =VLOOKUP(AD$6,'8. Uncertainty Results'!$B$434:$N$446,11,FALSE) -> 2225.7001 | AH8: =VLOOKUP(AH$6,'8. Uncertainty Results'!$B$223:$N$235,11,FALSE) -> -274.81451 | AI8: =VLOOKUP(AH$6,'8. Uncertainty Results'!$B$293:$N$305,11,FALSE) -> -362.66069 | AJ8: =VLOOKUP(AH$6,'8. Uncertainty Results'!$B$364:$N$376,11,FALSE) -> -366.63586 | AK8: =VLOOKUP(AH$6,'8. Uncertainty Results'!$B$434:$N$446,11,FALSE) -> -366.12352 | AL8: =VLOOKUP(AL$6,'8. Uncertainty Results'!$B$223:$N$235,11,FALSE) -> 8788.2794 | AM8: =VLOOKUP(AL$6,'8. Uncertainty Results'!$B$293:$N$305,11,FALSE) -> 9494.4469 | AN8: =VLOOKUP(AL$6,'8. Uncertainty Results'!$B$364:$N$376,11,FALSE) -> 9494.9831 | AO8: =VLOOKUP(AL$6,'8. Uncertainty Results'!$B$434:$N$446,11,FALSE) -> 9493.823 | AP8: =VLOOKUP(AP$6,'8. Uncertainty Results'!$B$223:$N$235,11,FALSE) -> 574.46896 | AQ8: =VLOOKUP(AP$6,'8. Uncertainty Results'!$B$293:$N$305,11,FALSE) -> 605.69177 | AR8: =VLOOKUP(AP$6,'8. Uncertainty Results'!$B$364:$N$376,11,FALSE) -> 609.19728 | AS8: =VLOOKUP(AP$6,'8. Uncertainty Results'!$B$434:$N$446,11,FALSE) -> 600.95255 | AT8: =VLOOKUP(AT$6,'8. Uncertainty Results'!$B$223:$N$235,11,FALSE) -> -10.237762 | AU8: =VLOOKUP(AT$6,'8. Uncertainty Results'!$B$293:$N$305,11,FALSE) -> -12.108743 | AV8: =VLOOKUP(AT$6,'8. Uncertainty Results'!$B$364:$N$376,11,FALSE) -> -9.3873163 | AW8: =VLOOKUP(AT$6,'8. Uncertainty Results'!$B$434:$N$446,11,FALSE) -> -14.686002 | AX8: =VLOOKUP(AX$6,'8. Uncertainty Results'!$B$223:$N$235,11,FALSE) -> 434.97039 | AY8: =VLOOKUP(AX$6,'8. Uncertainty Results'!$B$293:$N$305,11,FALSE) -> 550.96248 | AZ8: =VLOOKUP(AX$6,'8. Uncertainty Results'!$B$364:$N$376,11,FALSE) -> 552.19068 | BA8: =VLOOKUP(AX$6,'8. Uncertainty Results'!$B$434:$N$446,11,FALSE) -> 549.47023
A9: p50 | B9: =VLOOKUP(B$6,'8. Uncertainty Results'!$B$223:$N$235,12,FALSE) -> -68.219622 | C9: =VLOOKUP(B$6,'8. Uncertainty Results'!$B$293:$N$305,12,FALSE) -> -77.687367 | D9: =VLOOKUP(B$6,'8. Uncertainty Results'!$B$364:$N$376,12,FALSE) -> -75.32616 | E9: =VLOOKUP(B$6,'8. Uncertainty Results'!$B$434:$N$446,12,FALSE) -> -79.976633 | F9: =VLOOKUP(F$6,'8. Uncertainty Results'!$B$223:$N$235,12,FALSE) -> -148.49289 | G9: =VLOOKUP(F$6,'8. Uncertainty Results'!$B$293:$N$305,12,FALSE) -> -96.515456 | H9: =VLOOKUP(F$6,'8. Uncertainty Results'!$B$364:$N$376,12,FALSE) -> -79.43486 | I9: =VLOOKUP(F$6,'8. Uncertainty Results'!$B$434:$N$446,12,FALSE) -> -116.3588 | J9: =VLOOKUP(J$6,'8. Uncertainty Results'!$B$223:$N$235,12,FALSE) -> -45.287407 | K9: =VLOOKUP(J$6,'8. Uncertainty Results'!$B$293:$N$305,12,FALSE) -> 10.073609 | L9: =VLOOKUP(J$6,'8. Uncertainty Results'!$B$364:$N$376,12,FALSE) -> 28.380038 | M9: =VLOOKUP(J$6,'8. Uncertainty Results'!$B$434:$N$446,12,FALSE) -> -9.6769893 | N9: =VLOOKUP(N$6,'8. Uncertainty Results'!$B$223:$N$235,12,FALSE) -> -963.26078 | O9: =VLOOKUP(N$6,'8. Uncertainty Results'!$B$293:$N$305,12,FALSE) -> -3486.5863 | P9: =VLOOKUP(N$6,'8. Uncertainty Results'!$B$364:$N$376,12,FALSE) -> -3419.7338 | Q9: =VLOOKUP(N$6,'8. Uncertainty Results'!$B$434:$N$446,12,FALSE) -> -3465.3548 | R9: =VLOOKUP(R$6,'8. Uncertainty Results'!$B$223:$N$235,12,FALSE) -> -25.879549 | S9: =VLOOKUP(R$6,'8. Uncertainty Results'!$B$293:$N$305,12,FALSE) -> -41.361193 | T9: =VLOOKUP(R$6,'8. Uncertainty Results'!$B$364:$N$376,12,FALSE) -> -39.742932 | U9: =VLOOKUP(R$6,'8. Uncertainty Results'!$B$434:$N$446,12,FALSE) -> -44.169544 | V9: =VLOOKUP(V$6,'8. Uncertainty Results'!$B$223:$N$235,12,FALSE) -> -1095.5101 | W9: =VLOOKUP(V$6,'8. Uncertainty Results'!$B$293:$N$305,12,FALSE) -> -1581.8415 | X9: =VLOOKUP(V$6,'8. Uncertainty Results'!$B$364:$N$376,12,FALSE) -> -1482.6871 | Y9: =VLOOKUP(V$6,'8. Uncertainty Results'!$B$434:$N$446,12,FALSE) -> -1708.5345 | Z9: =VLOOKUP(Z$6,'8. Uncertainty Results'!$B$223:$N$235,12,FALSE) -> -20.592205 | AA9: =VLOOKUP(Z$6,'8. Uncertainty Results'!$B$293:$N$305,12,FALSE) -> -29.132273 | AB9: =VLOOKUP(Z$6,'8. Uncertainty Results'!$B$364:$N$376,12,FALSE) -> -28.45022 | AC9: =VLOOKUP(Z$6,'8. Uncertainty Results'!$B$434:$N$446,12,FALSE) -> -30.744778 | AD9: =VLOOKUP(AD$6,'8. Uncertainty Results'!$B$223:$N$235,12,FALSE) -> 3527.7743 | AE9: =VLOOKUP(AD$6,'8. Uncertainty Results'!$B$293:$N$305,12,FALSE) -> 3274.5246 | AF9: =VLOOKUP(AD$6,'8. Uncertainty Results'!$B$364:$N$376,12,FALSE) -> 3291.0124 | AG9: =VLOOKUP(AD$6,'8. Uncertainty Results'!$B$434:$N$446,12,FALSE) -> 3254.684 | AH9: =VLOOKUP(AH$6,'8. Uncertainty Results'!$B$223:$N$235,12,FALSE) -> -115.79657 | AI9: =VLOOKUP(AH$6,'8. Uncertainty Results'!$B$293:$N$305,12,FALSE) -> -401.30175 | AJ9: =VLOOKUP(AH$6,'8. Uncertainty Results'!$B$364:$N$376,12,FALSE) -> -400.28433 | AK9: =VLOOKUP(AH$6,'8. Uncertainty Results'!$B$434:$N$446,12,FALSE) -> -404.49632 | AL9: =VLOOKUP(AL$6,'8. Uncertainty Results'!$B$223:$N$235,12,FALSE) -> 11491.563 | AM9: =VLOOKUP(AL$6,'8. Uncertainty Results'!$B$293:$N$305,12,FALSE) -> 12968.573 | AN9: =VLOOKUP(AL$6,'8. Uncertainty Results'!$B$364:$N$376,12,FALSE) -> 12969.177 | AO9: =VLOOKUP(AL$6,'8. Uncertainty Results'!$B$434:$N$446,12,FALSE) -> 12967.877 | AP9: =VLOOKUP(AP$6,'8. Uncertainty Results'!$B$223:$N$235,12,FALSE) -> 925.29709 | AQ9: =VLOOKUP(AP$6,'8. Uncertainty Results'!$B$293:$N$305,12,FALSE) -> 873.44777 | AR9: =VLOOKUP(AP$6,'8. Uncertainty Results'!$B$364:$N$376,12,FALSE) -> 877.78902 | AS9: =VLOOKUP(AP$6,'8. Uncertainty Results'!$B$434:$N$446,12,FALSE) -> 868.01472 | AT9: =VLOOKUP(AT$6,'8. Uncertainty Results'!$B$223:$N$235,12,FALSE) -> -4.573901 | AU9: =VLOOKUP(AT$6,'8. Uncertainty Results'!$B$293:$N$305,12,FALSE) -> -2.2346981 | AV9: =VLOOKUP(AT$6,'8. Uncertainty Results'!$B$364:$N$376,12,FALSE) -> 0.76973057 | AW9: =VLOOKUP(AT$6,'8. Uncertainty Results'!$B$434:$N$446,12,FALSE) -> -5.83439 | AX9: =VLOOKUP(AX$6,'8. Uncertainty Results'!$B$223:$N$235,12,FALSE) -> 722.50344 | AY9: =VLOOKUP(AX$6,'8. Uncertainty Results'!$B$293:$N$305,12,FALSE) -> 789.93934 | AZ9: =VLOOKUP(AX$6,'8. Uncertainty Results'!$B$364:$N$376,12,FALSE) -> 791.53188 | BA9: =VLOOKUP(AX$6,'8. Uncertainty Results'!$B$434:$N$446,12,FALSE) -> 787.95094
A10: p90 | B10: =VLOOKUP(B$6,'8. Uncertainty Results'!$B$223:$N$235,13,FALSE) -> -106.18866 | C10: =VLOOKUP(B$6,'8. Uncertainty Results'!$B$293:$N$305,13,FALSE) -> -113.38093 | D10: =VLOOKUP(B$6,'8. Uncertainty Results'!$B$364:$N$376,13,FALSE) -> -111.75646 | E10: =VLOOKUP(B$6,'8. Uncertainty Results'!$B$434:$N$446,13,FALSE) -> -116.74002 | F10: =VLOOKUP(F$6,'8. Uncertainty Results'!$B$223:$N$235,13,FALSE) -> -162.84456 | G10: =VLOOKUP(F$6,'8. Uncertainty Results'!$B$293:$N$305,13,FALSE) -> -101.21278 | H10: =VLOOKUP(F$6,'8. Uncertainty Results'!$B$364:$N$376,13,FALSE) -> -81.210838 | I10: =VLOOKUP(F$6,'8. Uncertainty Results'!$B$434:$N$446,13,FALSE) -> -125.64048 | J10: =VLOOKUP(J$6,'8. Uncertainty Results'!$B$223:$N$235,13,FALSE) -> 9.7221124 | K10: =VLOOKUP(J$6,'8. Uncertainty Results'!$B$293:$N$305,13,FALSE) -> 79.808199 | L10: =VLOOKUP(J$6,'8. Uncertainty Results'!$B$364:$N$376,13,FALSE) -> 100.62441 | M10: =VLOOKUP(J$6,'8. Uncertainty Results'!$B$434:$N$446,13,FALSE) -> 55.989892 | N10: =VLOOKUP(N$6,'8. Uncertainty Results'!$B$223:$N$235,13,FALSE) -> -1430.7913 | O10: =VLOOKUP(N$6,'8. Uncertainty Results'!$B$293:$N$305,13,FALSE) -> -6271.9166 | P10: =VLOOKUP(N$6,'8. Uncertainty Results'!$B$364:$N$376,13,FALSE) -> -6184.9009 | Q10: =VLOOKUP(N$6,'8. Uncertainty Results'!$B$434:$N$446,13,FALSE) -> -6311.7539 | R10: =VLOOKUP(R$6,'8. Uncertainty Results'!$B$223:$N$235,13,FALSE) -> -16.359023 | S10: =VLOOKUP(R$6,'8. Uncertainty Results'!$B$293:$N$305,13,FALSE) -> -34.653405 | T10: =VLOOKUP(R$6,'8. Uncertainty Results'!$B$364:$N$376,13,FALSE) -> -31.413365 | U10: =VLOOKUP(R$6,'8. Uncertainty Results'!$B$434:$N$446,13,FALSE) -> -37.318145 | V10: =VLOOKUP(V$6,'8. Uncertainty Results'!$B$223:$N$235,13,FALSE) -> -1353.9333 | W10: =VLOOKUP(V$6,'8. Uncertainty Results'!$B$293:$N$305,13,FALSE) -> -2175.7846 | X10: =VLOOKUP(V$6,'8. Uncertainty Results'!$B$364:$N$376,13,FALSE) -> -2079.7111 | Y10: =VLOOKUP(V$6,'8. Uncertainty Results'!$B$434:$N$446,13,FALSE) -> -2322.2102 | Z10: =VLOOKUP(Z$6,'8. Uncertainty Results'!$B$223:$N$235,13,FALSE) -> -21.708512 | AA10: =VLOOKUP(Z$6,'8. Uncertainty Results'!$B$293:$N$305,13,FALSE) -> -27.533843 | AB10: =VLOOKUP(Z$6,'8. Uncertainty Results'!$B$364:$N$376,13,FALSE) -> -25.175675 | AC10: =VLOOKUP(Z$6,'8. Uncertainty Results'!$B$434:$N$446,13,FALSE) -> -29.442218 | AD10: =VLOOKUP(AD$6,'8. Uncertainty Results'!$B$223:$N$235,13,FALSE) -> 4963.3598 | AE10: =VLOOKUP(AD$6,'8. Uncertainty Results'!$B$293:$N$305,13,FALSE) -> 4168.9184 | AF10: =VLOOKUP(AD$6,'8. Uncertainty Results'!$B$364:$N$376,13,FALSE) -> 4189.2721 | AG10: =VLOOKUP(AD$6,'8. Uncertainty Results'!$B$434:$N$446,13,FALSE) -> 4144.1453 | AH10: =VLOOKUP(AH$6,'8. Uncertainty Results'!$B$223:$N$235,13,FALSE) -> 163.74008 | AI10: =VLOOKUP(AH$6,'8. Uncertainty Results'!$B$293:$N$305,13,FALSE) -> -431.26041 | AJ10: =VLOOKUP(AH$6,'8. Uncertainty Results'!$B$364:$N$376,13,FALSE) -> -431.60881 | AK10: =VLOOKUP(AH$6,'8. Uncertainty Results'!$B$434:$N$446,13,FALSE) -> -436.55592 | AL10: =VLOOKUP(AL$6,'8. Uncertainty Results'!$B$223:$N$235,13,FALSE) -> 14623.825 | AM10: =VLOOKUP(AL$6,'8. Uncertainty Results'!$B$293:$N$305,13,FALSE) -> 16883.115 | AN10: =VLOOKUP(AL$6,'8. Uncertainty Results'!$B$364:$N$376,13,FALSE) -> 16883.702 | AO10: =VLOOKUP(AL$6,'8. Uncertainty Results'!$B$434:$N$446,13,FALSE) -> 16881.991 | AP10: =VLOOKUP(AP$6,'8. Uncertainty Results'!$B$223:$N$235,13,FALSE) -> 1261.0647 | AQ10: =VLOOKUP(AP$6,'8. Uncertainty Results'!$B$293:$N$305,13,FALSE) -> 1114.1856 | AR10: =VLOOKUP(AP$6,'8. Uncertainty Results'!$B$364:$N$376,13,FALSE) -> 1119.628 | AS10: =VLOOKUP(AP$6,'8. Uncertainty Results'!$B$434:$N$446,13,FALSE) -> 1107.6936 | AT10: =VLOOKUP(AT$6,'8. Uncertainty Results'!$B$223:$N$235,13,FALSE) -> 10.130193 | AU10: =VLOOKUP(AT$6,'8. Uncertainty Results'!$B$293:$N$305,13,FALSE) -> 21.408984 | AV10: =VLOOKUP(AT$6,'8. Uncertainty Results'!$B$364:$N$376,13,FALSE) -> 25.402612 | AW10: =VLOOKUP(AT$6,'8. Uncertainty Results'!$B$434:$N$446,13,FALSE) -> 17.519457 | AX10: =VLOOKUP(AX$6,'8. Uncertainty Results'!$B$223:$N$235,13,FALSE) -> 1027.4046 | AY10: =VLOOKUP(AX$6,'8. Uncertainty Results'!$B$293:$N$305,13,FALSE) -> 1046.0953 | AZ10: =VLOOKUP(AX$6,'8. Uncertainty Results'!$B$364:$N$376,13,FALSE) -> 1048.1631 | BA10: =VLOOKUP(AX$6,'8. Uncertainty Results'!$B$434:$N$446,13,FALSE) -> 1043.6689
A12: By HUC8 watershed, based on increasing availability
B14: SS | F14: UQ | J14: BUR | N14: RSCV | R14: SBSV | V14: CSF | Z14: FLSSV | AD14: BS | AH14: BB | AL14: SFC | AP14: UB | AT14: UCKS
B15: SSP1 | C15: SSP2 | D15: SSP3 | E15: SSP5 | F15: SSP1 | G15: SSP2 | H15: SSP3 | I15: SSP5 | J15: SSP1 | K15: SSP2 | L15: SSP3 | M15: SSP5 | N15: SSP1 | O15: SSP2 | P15: SSP3 | Q15: SSP5 | R15: SSP1 | S15: SSP2 | T15: SSP3 | U15: SSP5 | V15: SSP1 | W15: SSP2 | X15: SSP3 | Y15: SSP5 | Z15: SSP1 | AA15: SSP2 | AB15: SSP3 | AC15: SSP5 | AD15: SSP1 | AE15: SSP2 | AF15: SSP3 | AG15: SSP5 | AH15: SSP1 | AI15: SSP2 | AJ15: SSP3 | AK15: SSP5 | AL15: SSP1 | AM15: SSP2 | AN15: SSP3 | AO15: SSP5 | AP15: SSP1 | AQ15: SSP2 | AR15: SSP3 | AS15: SSP5 | AT15: SSP1 | AU15: SSP2 | AV15: SSP3 | AW15: SSP5
A16: p10 | B16: {=N8:Q10} -> -389.82744 | C16: -1468.7587 | D16: -1464.2888 | E16: -1487.6343 | F16: {=AH8:AK10} -> -274.81451 | G16: -362.66069 | H16: -366.63586 | I16: -366.12352 | J16: {=F8:I10} -> -137.97431 | K16: -97.529141 | L16: -83.630003 | M16: -113.66207 | N16: {=B8:E10} -> -47.925476 | O16: -55.898533 | P16: -54.233805 | Q16: -57.603329 | R16: {=Z8:AC10} -> -27.863979 | S16: -35.516203 | T16: -34.412659 | U16: -36.626251 | V16: {=R8:U10} -> -29.882623 | W16: -40.003379 | X16: -38.893615 | Y16: -42.51057 | Z16: {=AT8:AW10} -> -10.237762 | AA16: -12.108743 | AB16: -9.3873163 | AC16: -14.686002 | AD16: {=J8:M10} -> -86.6769 | AE16: -45.586065 | AF16: -29.883434 | AG16: -60.868897 | AH16: {=AX8:BA10} -> 434.97039 | AI16: 550.96248 | AJ16: 552.19068 | AK16: 549.47023 | AL16: {=AP8:AS10} -> 574.46896 | AM16: 605.69177 | AN16: 609.19728 | AO16: 600.95255 | AP16: {=AD8:AG10} -> 2232.013 | AQ16: 2241.4245 | AR16: 2254.1925 | AS16: 2225.7001 | AT16: {=AL8:AO10} -> 8788.2794 | AU16: 9494.4469 | AV16: 9494.9831 | AW16: 9493.823
